Workbook
Name emenda: #REF!
Name FNDE: #REF!
Name jjhkjh: #REF!
Name Previsao_dos_Fundos_PREVISFUNDO_Listar: #REF!
Name saljdalçfakjsd: #REF!

Sheet FNDE
A1: Ano/Período | B1: UF | C1: Cód. Município | D1: Município | E1: Disponibilidade de Informações
A2: 2025 Anual | B2: AC | C2: 120025 | D2: Epitaciolândia | E2: Sem Transmissão
A3: 2025 Anual | B3: AM | C3: 130063 | D3: Beruri | E3: Sem Transmissão
A4: 2025 Anual | B4: AM | C4: 130070 | D4: Boca do Acre | E4: Sem Transmissão
A5: 2025 Anual | B5: AM | C5: 130083 | D5: Caapiranga | E5: Sem Transmissão
A6: 2025 Anual | B6: AM | C6: 130140 | D6: Eirunepé | E6: Sem Transmissão
A7: 2025 Anual | B7: AM | C7: 130180 | D7: Ipixuna | E7: Sem Transmissão
A8: 2025 Anual | B8: AM | C8: 130195 | D8: Itamarati | E8: Sem Transmissão
A9: 2025 Anual | B9: AM | C9: 130220 | D9: Juruá | E9: Sem Transmissão
A10: 2025 Anual | B10: AM | C10: 130240 | D10: Lábrea | E10: Sem Transmissão
A11: 2025 Anual | B11: AM | C11: 130310 | D11: Nova Olinda do Norte | E11: Sem Transmissão
A12: 2025 Anual | B12: AM | C12: 130350 | D12: Pauini | E12: Sem Transmissão
A13: 2025 Anual | B13: RR | C13: 140028 | D13: Iracema | E13: Sem Transmissão
... A61: 2025 Anual | B61: MG | C61: 31 | D61: Minas Gerais | E61: Sem Transmissão

Sheet CCONF
A1: CÓDIGO_IBGE | B1: UF | C1: ENTE | D1: MOTIVO
A2: 1600279 | B2: AP | C2: Laranjal do Jari - AP | D2: Não enviou a MSC de encerramento de 2025 | E2: =IF(OR(A2=A1,A2=A3),"ERRO","OK") -> OK
A3: 5205059 | B3: GO | C3: Castelândia - GO | D3: Não enviou a MSC de encerramento de 2025 | E3: =IF(OR(A3=A2,A3=A4),"ERRO","OK") -> OK
A4: 5219738 | B4: GO | C4: Santo Antônio de Goiás - GO | D4: Enviou a MSC de encerramento com alguma RECEITA LÍQUIDA negativa | E4: =IF(OR(A4=A3,A4=A5),"ERRO","OK") -> OK
A5: 5220264 | B5: GO | C5: São Miguel do Passa Quatro - GO | D5: Enviou a MSC de encerramento com alguma RECEITA LÍQUIDA negativa | E5: =IF(OR(A5=A4,A5=A6),"ERRO","OK") -> OK
A6: 2110237 | B6: MA | C6: Santana do Maranhão - MA | D6: Enviou a MSC de encerramento com a COTA-PARTE de ICMS zerada ou negativa | E6: =IF(OR(A6=A5,A6=A7),"ERRO","OK") -> OK
A7: 2112456 | B7: MA | C7: Turilândia - MA | D7: Não enviou a MSC de encerramento de 2025 | E7: =IF(OR(A7=A6,A7=A8),"ERRO","OK") -> OK
A8: 5106273 | B8: MT | C8: Novo Horizonte do Norte - MT | D8: Não enviou a MSC de encerramento de 2025 | E8: =IF(OR(A8=A7,A8=A9),"ERRO","OK") -> OK
A9: 5107859 | B9: MT | C9: São Félix do Araguaia - MT | D9: Enviou a MSC de encerramento sem o detalhamento necessário ou com as Receitas zeradas | E9: =IF(OR(A9=A8,A9=A10),"ERRO","OK") -> OK
A10: 4104709 | B10: PR | C10: Carlópolis - PR | D10: Não enviou a MSC de encerramento de 2025 | E10: =IF(OR(A10=A9,A10=A11),"ERRO","OK") -> OK
A11: 4106456 | B11: PR | C11: Coronel Domingos Soares - PR | D11: Não enviou a MSC de encerramento de 2025 | E11: =IF(OR(A11=A10,A11=A12),"ERRO","OK") -> OK
A12: 3301801 | B12: RJ | C12: Engenheiro Paulo de Frontin - RJ | D12: Não enviou a MSC de encerramento de 2025 | E12: =IF(OR(A12=A11,A12=A13),"ERRO","OK") -> OK
A13: 3306305 | B13: RJ | C13: Volta Redonda - RJ | D13: Enviou a MSC de encerramento sem o detalhamento necessário ou com as Receitas zeradas | E13: =IF(OR(A13=A12,A13=A14),"ERRO","OK") -> OK
... A18: 1718550 | B18: TO | C18: Riachinho - TO | D18: Não enviou a MSC de encerramento de 2025 | E18: =IF(OR(A18=A17,A18=A19),"ERRO","OK") -> OK

Sheet Base de dados STN
A1: UF | B1: Ente Federado | C1: Código IBGE | D1: CHECAGEM RÁPIDA | E1: SITUAÇÃO
B2: Rondônia | C2: 11 | D2: =IF(ISERROR(VLOOKUP(C2,CCONF!$A$2:$D$1020,4,FALSE)),"SIM","NÃO") -> SIM | E2: =IF(ISERROR(VLOOKUP(C2,CCONF!$A$2:$D$1020,4,FALSE)),"",VLOOKUP(C2,CCONF!$A$2:$D$1020,4,FALSE)) | F2: TOTAL | G2: =COUNTIF(D:D,"NÃO") -> 17
B3: Acre | C3: 12 | D3: =IF(ISERROR(VLOOKUP(C3,CCONF!$A$2:$D$1020,4,FALSE)),"SIM","NÃO") -> SIM | E3: =IF(ISERROR(VLOOKUP(C3,CCONF!$A$2:$D$1020,4,FALSE)),"",VLOOKUP(C3,CCONF!$A$2:$D$1020,4,FALSE))
B4: Amazonas | C4: 13 | D4: =IF(ISERROR(VLOOKUP(C4,CCONF!$A$2:$D$1020,4,FALSE)),"SIM","NÃO") -> SIM | E4: =IF(ISERROR(VLOOKUP(C4,CCONF!$A$2:$D$1020,4,FALSE)),"",VLOOKUP(C4,CCONF!$A$2:$D$1020,4,FALSE))
B5: Roraima | C5: 14 | D5: =IF(ISERROR(VLOOKUP(C5,CCONF!$A$2:$D$1020,4,FALSE)),"SIM","NÃO") -> SIM | E5: =IF(ISERROR(VLOOKUP(C5,CCONF!$A$2:$D$1020,4,FALSE)),"",VLOOKUP(C5,CCONF!$A$2:$D$1020,4,FALSE))
B6: Pará | C6: 15 | D6: =IF(ISERROR(VLOOKUP(C6,CCONF!$A$2:$D$1020,4,FALSE)),"SIM","NÃO") -> SIM | E6: =IF(ISERROR(VLOOKUP(C6,CCONF!$A$2:$D$1020,4,FALSE)),"",VLOOKUP(C6,CCONF!$A$2:$D$1020,4,FALSE))
B7: Amapá | C7: 16 | D7: =IF(ISERROR(VLOOKUP(C7,CCONF!$A$2:$D$1020,4,FALSE)),"SIM","NÃO") -> SIM | E7: =IF(ISERROR(VLOOKUP(C7,CCONF!$A$2:$D$1020,4,FALSE)),"",VLOOKUP(C7,CCONF!$A$2:$D$1020,4,FALSE))
B8: Tocantins | C8: 17 | D8: =IF(ISERROR(VLOOKUP(C8,CCONF!$A$2:$D$1020,4,FALSE)),"SIM","NÃO") -> SIM | E8: =IF(ISERROR(VLOOKUP(C8,CCONF!$A$2:$D$1020,4,FALSE)),"",VLOOKUP(C8,CCONF!$A$2:$D$1020,4,FALSE))
B9: Maranhão | C9: 21 | D9: =IF(ISERROR(VLOOKUP(C9,CCONF!$A$2:$D$1020,4,FALSE)),"SIM","NÃO") -> SIM | E9: =IF(ISERROR(VLOOKUP(C9,CCONF!$A$2:$D$1020,4,FALSE)),"",VLOOKUP(C9,CCONF!$A$2:$D$1020,4,FALSE))
B10: Piauí | C10: 22 | D10: =IF(ISERROR(VLOOKUP(C10,CCONF!$A$2:$D$1020,4,FALSE)),"SIM","NÃO") -> SIM | E10: =IF(ISERROR(VLOOKUP(C10,CCONF!$A$2:$D$1020,4,FALSE)),"",VLOOKUP(C10,CCONF!$A$2:$D$1020,4,FALSE))
B11: Ceará | C11: 23 | D11: =IF(ISERROR(VLOOKUP(C11,CCONF!$A$2:$D$1020,4,FALSE)),"SIM","NÃO") -> SIM | E11: =IF(ISERROR(VLOOKUP(C11,CCONF!$A$2:$D$1020,4,FALSE)),"",VLOOKUP(C11,CCONF!$A$2:$D$1020,4,FALSE))
B12: Rio Grande do Norte | C12: 24 | D12: =IF(ISERROR(VLOOKUP(C12,CCONF!$A$2:$D$1020,4,FALSE)),"SIM","NÃO") -> SIM | E12: =IF(ISERROR(VLOOKUP(C12,CCONF!$A$2:$D$1020,4,FALSE)),"",VLOOKUP(C12,CCONF!$A$2:$D$1020,4,FALSE))
B13: Paraíba | C13: 25 | D13: =IF(ISERROR(VLOOKUP(C13,CCONF!$A$2:$D$1020,4,FALSE)),"SIM","NÃO") -> SIM | E13: =IF(ISERROR(VLOOKUP(C13,CCONF!$A$2:$D$1020,4,FALSE)),"",VLOOKUP(C13,CCONF!$A$2:$D$1020,4,FALSE))
B14: Pernambuco | C14: 26 | D14: =IF(ISERROR(VLOOKUP(C14,CCONF!$A$2:$D$1020,4,FALSE)),"SIM","NÃO") -> SIM | E14: =IF(ISERROR(VLOOKUP(C14,CCONF!$A$2:$D$1020,4,FALSE)),"",VLOOKUP(C14,CCONF!$A$2:$D$1020,4,FALSE))
... B28: Distrito Federal | C28: 53 | D28: =IF(ISERROR(VLOOKUP(C28,CCONF!$A$2:$D$1020,4,FALSE)),"SIM","NÃO") -> SIM | E28: =IF(ISERROR(VLOOKUP(C28,CCONF!$A$2:$D$1020,4,FALSE)),"",VLOOKUP(C28,CCONF!$A$2:$D$1020,4,FALSE))
A29: RO | B29: Alta Floresta D'Oeste | C29: 1100015 | D29: =IF(ISERROR(VLOOKUP(C29,CCONF!$A$2:$D$1020,4,FALSE)),"SIM","NÃO") -> SIM | E29: =IF(ISERROR(VLOOKUP(C29,CCONF!$A$2:$D$1020,4,FALSE)),"",VLOOKUP(C29,CCONF!$A$2:$D$1020,4,FALSE))
A30: RO | B30: Ariquemes | C30: 1100023 | D30: =IF(ISERROR(VLOOKUP(C30,CCONF!$A$2:$D$1020,4,FALSE)),"SIM","NÃO") -> SIM | E30: =IF(ISERROR(VLOOKUP(C30,CCONF!$A$2:$D$1020,4,FALSE)),"",VLOOKUP(C30,CCONF!$A$2:$D$1020,4,FALSE))
A31: RO | B31: Cabixi | C31: 1100031 | D31: =IF(ISERROR(VLOOKUP(C31,CCONF!$A$2:$D$1020,4,FALSE)),"SIM","NÃO") -> SIM | E31: =IF(ISERROR(VLOOKUP(C31,CCONF!$A$2:$D$1020,4,FALSE)),"",VLOOKUP(C31,CCONF!$A$2:$D$1020,4,FALSE))
A32: RO | B32: Cacoal | C32: 1100049 | D32: =IF(ISERROR(VLOOKUP(C32,CCONF!$A$2:$D$1020,4,FALSE)),"SIM","NÃO") -> SIM | E32: =IF(ISERROR(VLOOKUP(C32,CCONF!$A$2:$D$1020,4,FALSE)),"",VLOOKUP(C32,CCONF!$A$2:$D$1020,4,FALSE))
A33: RO | B33: Cerejeiras | C33: 1100056 | D33: =IF(ISERROR(VLOOKUP(C33,CCONF!$A$2:$D$1020,4,FALSE)),"SIM","NÃO") -> SIM | E33: =IF(ISERROR(VLOOKUP(C33,CCONF!$A$2:$D$1020,4,FALSE)),"",VLOOKUP(C33,CCONF!$A$2:$D$1020,4,FALSE))
A34: RO | B34: Colorado do Oeste | C34: 1100064 | D34: =IF(ISERROR(VLOOKUP(C34,CCONF!$A$2:$D$1020,4,FALSE)),"SIM","NÃO") -> SIM | E34: =IF(ISERROR(VLOOKUP(C34,CCONF!$A$2:$D$1020,4,FALSE)),"",VLOOKUP(C34,CCONF!$A$2:$D$1020,4,FALSE))
A35: RO | B35: Corumbiara | C35: 1100072 | D35: =IF(ISERROR(VLOOKUP(C35,CCONF!$A$2:$D$1020,4,FALSE)),"SIM","NÃO") -> SIM | E35: =IF(ISERROR(VLOOKUP(C35,CCONF!$A$2:$D$1020,4,FALSE)),"",VLOOKUP(C35,CCONF!$A$2:$D$1020,4,FALSE))
A36: RO | B36: Costa Marques | C36: 1100080 | D36: =IF(ISERROR(VLOOKUP(C36,CCONF!$A$2:$D$1020,4,FALSE)),"SIM","NÃO") -> SIM | E36: =IF(ISERROR(VLOOKUP(C36,CCONF!$A$2:$D$1020,4,FALSE)),"",VLOOKUP(C36,CCONF!$A$2:$D$1020,4,FALSE))
A37: RO | B37: Espigão D'Oeste | C37: 1100098 | D37: =IF(ISERROR(VLOOKUP(C37,CCONF!$A$2:$D$1020,4,FALSE)),"SIM","NÃO") -> SIM | E37: =IF(ISERROR(VLOOKUP(C37,CCONF!$A$2:$D$1020,4,FALSE)),"",VLOOKUP(C37,CCONF!$A$2:$D$1020,4,FALSE))
A38: RO | B38: Guajará-Mirim | C38: 1100106 | D38: =IF(ISERROR(VLOOKUP(C38,CCONF!$A$2:$D$1020,4,FALSE)),"SIM","NÃO") -> SIM | E38: =IF(ISERROR(VLOOKUP(C38,CCONF!$A$2:$D$1020,4,FALSE)),"",VLOOKUP(C38,CCONF!$A$2:$D$1020,4,FALSE))
A39: RO | B39: Jaru | C39: 1100114 | D39: =IF(ISERROR(VLOOKUP(C39,CCONF!$A$2:$D$1020,4,FALSE)),"SIM","NÃO") -> SIM | E39: =IF(ISERROR(VLOOKUP(C39,CCONF!$A$2:$D$1020,4,FALSE)),"",VLOOKUP(C39,CCONF!$A$2:$D$1020,4,FALSE))
A40: RO | B40: Ji-Paraná | C40: 1100122 | D40: =IF(ISERROR(VLOOKUP(C40,CCONF!$A$2:$D$1020,4,FALSE)),"SIM","NÃO") -> SIM | E40: =IF(ISERROR(VLOOKUP(C40,CCONF!$A$2:$D$1020,4,FALSE)),"",VLOOKUP(C40,CCONF!$A$2:$D$1020,4,FALSE))
... A5597: GO | B5597: Vila Propício | C5597: 5222302 | D5597: =IF(ISERROR(VLOOKUP(C5597,CCONF!$A$2:$D$1020,4,FALSE)),"SIM","NÃO") -> SIM | E5597: =IF(ISERROR(VLOOKUP(C5597,CCONF!$A$2:$D$1020,4,FALSE)),"",VLOOKUP(C5597,CCONF!$A$2:$D$1020,4,FALSE))

Sheet Compilação STN e FNDE
A1: UF | B1: Ente Federado | C1: Código IBGE | E1: Habilitação 163-A? | F1: Habilitação art. 38? | G1: Total inab 163 | H1: Total inab 38 | I1: Total inab 163 e 38 | J1: Total inab 163 ou 38
A2: RO | B2: Rondônia | C2: 11 | D2: =C2 -> 11 | E2: ='Base de dados STN'!D2 -> SIM | F2: =IF(ISERROR(VLOOKUP(D2,FNDE!$C$2:$D$932,1,FALSE)),"SIM","NÃO") -> SIM | G2: =IF(E2="Não",1,0) -> 0 | H2: =IF(F2="Não",1,0) -> 0 | I2: =IF(AND(E2="Não",F2="Não"),1,0) -> 0 | J2: =IF(OR(E2="Não",F2="Não"),1,0) -> 0
A3: AC | B3: Acre | C3: 12 | D3: =C3 -> 12 | E3: ='Base de dados STN'!D3 -> SIM | F3: =IF(ISERROR(VLOOKUP(D3,FNDE!$C$2:$D$932,1,FALSE)),"SIM","NÃO") -> SIM | G3: =IF(E3="Não",1,0) -> 0 | H3: =IF(F3="Não",1,0) -> 0 | I3: =IF(AND(E3="Não",F3="Não"),1,0) -> 0 | J3: =IF(OR(E3="Não",F3="Não"),1,0) -> 0
A4: AM | B4: Amazonas | C4: 13 | D4: =C4 -> 13 | E4: ='Base de dados STN'!D4 -> SIM | F4: =IF(ISERROR(VLOOKUP(D4,FNDE!$C$2:$D$932,1,FALSE)),"SIM","NÃO") -> SIM | G4: =IF(E4="Não",1,0) -> 0 | H4: =IF(F4="Não",1,0) -> 0 | I4: =IF(AND(E4="Não",F4="Não"),1,0) -> 0 | J4: =IF(OR(E4="Não",F4="Não"),1,0) -> 0
A5: RR | B5: Roraima | C5: 14 | D5: =C5 -> 14 | E5: ='Base de dados STN'!D5 -> SIM | F5: =IF(ISERROR(VLOOKUP(D5,FNDE!$C$2:$D$932,1,FALSE)),"SIM","NÃO") -> SIM | G5: =IF(E5="Não",1,0) -> 0 | H5: =IF(F5="Não",1,0) -> 0 | I5: =IF(AND(E5="Não",F5="Não"),1,0) -> 0 | J5: =IF(OR(E5="Não",F5="Não"),1,0) -> 0
A6: PA | B6: Pará | C6: 15 | D6: =C6 -> 15 | E6: ='Base de dados STN'!D6 -> SIM | F6: =IF(ISERROR(VLOOKUP(D6,FNDE!$C$2:$D$932,1,FALSE)),"SIM","NÃO") -> SIM | G6: =IF(E6="Não",1,0) -> 0 | H6: =IF(F6="Não",1,0) -> 0 | I6: =IF(AND(E6="Não",F6="Não"),1,0) -> 0 | J6: =IF(OR(E6="Não",F6="Não"),1,0) -> 0
A7: AP | B7: Amapá | C7: 16 | D7: =C7 -> 16 | E7: ='Base de dados STN'!D7 -> SIM | F7: =IF(ISERROR(VLOOKUP(D7,FNDE!$C$2:$D$932,1,FALSE)),"SIM","NÃO") -> SIM | G7: =IF(E7="Não",1,0) -> 0 | H7: =IF(F7="Não",1,0) -> 0 | I7: =IF(AND(E7="Não",F7="Não"),1,0) -> 0 | J7: =IF(OR(E7="Não",F7="Não"),1,0) -> 0
A8: TO | B8: Tocantins | C8: 17 | D8: =C8 -> 17 | E8: ='Base de dados STN'!D8 -> SIM | F8: =IF(ISERROR(VLOOKUP(D8,FNDE!$C$2:$D$932,1,FALSE)),"SIM","NÃO") -> SIM | G8: =IF(E8="Não",1,0) -> 0 | H8: =IF(F8="Não",1,0) -> 0 | I8: =IF(AND(E8="Não",F8="Não"),1,0) -> 0 | J8: =IF(OR(E8="Não",F8="Não"),1,0) -> 0
A9: MA | B9: Maranhão | C9: 21 | D9: =C9 -> 21 | E9: ='Base de dados STN'!D9 -> SIM | F9: =IF(ISERROR(VLOOKUP(D9,FNDE!$C$2:$D$932,1,FALSE)),"SIM","NÃO") -> SIM | G9: =IF(E9="Não",1,0) -> 0 | H9: =IF(F9="Não",1,0) -> 0 | I9: =IF(AND(E9="Não",F9="Não"),1,0) -> 0 | J9: =IF(OR(E9="Não",F9="Não"),1,0) -> 0
A10: PI | B10: Piauí | C10: 22 | D10: =C10 -> 22 | E10: ='Base de dados STN'!D10 -> SIM | F10: =IF(ISERROR(VLOOKUP(D10,FNDE!$C$2:$D$932,1,FALSE)),"SIM","NÃO") -> SIM | G10: =IF(E10="Não",1,0) -> 0 | H10: =IF(F10="Não",1,0) -> 0 | I10: =IF(AND(E10="Não",F10="Não"),1,0) -> 0 | J10: =IF(OR(E10="Não",F10="Não"),1,0) -> 0
A11: CE | B11: Ceará | C11: 23 | D11: =C11 -> 23 | E11: ='Base de dados STN'!D11 -> SIM | F11: =IF(ISERROR(VLOOKUP(D11,FNDE!$C$2:$D$932,1,FALSE)),"SIM","NÃO") -> SIM | G11: =IF(E11="Não",1,0) -> 0 | H11: =IF(F11="Não",1,0) -> 0 | I11: =IF(AND(E11="Não",F11="Não"),1,0) -> 0 | J11: =IF(OR(E11="Não",F11="Não"),1,0) -> 0
A12: RN | B12: Rio Grande do Norte | C12: 24 | D12: =C12 -> 24 | E12: ='Base de dados STN'!D12 -> SIM | F12: =IF(ISERROR(VLOOKUP(D12,FNDE!$C$2:$D$932,1,FALSE)),"SIM","NÃO") -> SIM | G12: =IF(E12="Não",1,0) -> 0 | H12: =IF(F12="Não",1,0) -> 0 | I12: =IF(AND(E12="Não",F12="Não"),1,0) -> 0 | J12: =IF(OR(E12="Não",F12="Não"),1,0) -> 0
A13: PB | B13: Paraíba | C13: 25 | D13: =C13 -> 25 | E13: ='Base de dados STN'!D13 -> SIM | F13: =IF(ISERROR(VLOOKUP(D13,FNDE!$C$2:$D$932,1,FALSE)),"SIM","NÃO") -> SIM | G13: =IF(E13="Não",1,0) -> 0 | H13: =IF(F13="Não",1,0) -> 0 | I13: =IF(AND(E13="Não",F13="Não"),1,0) -> 0 | J13: =IF(OR(E13="Não",F13="Não"),1,0) -> 0
... A28: DF | B28: Distrito Federal | C28: 53 | D28: =C28 -> 53 | E28: ='Base de dados STN'!D28 -> SIM | F28: =IF(ISERROR(VLOOKUP(D28,FNDE!$C$2:$D$932,1,FALSE)),"SIM","NÃO") -> SIM | G28: =IF(E28="Não",1,0) -> 0 | H28: =IF(F28="Não",1,0) -> 0 | I28: =IF(AND(E28="Não",F28="Não"),1,0) -> 0 | J28: =IF(OR(E28="Não",F28="Não"),1,0) -> 0
A29: RO | B29: Alta Floresta D'Oeste | C29: 1100015 | D29: =ROUNDDOWN(C29/10,0) -> 110001 | E29: ='Base de dados STN'!D29 -> SIM | F29: =IF(ISERROR(VLOOKUP(D29,FNDE!$C$2:$D$932,1,FALSE)),"SIM","NÃO") -> SIM | G29: =IF(E29="Não",1,0) -> 0 | H29: =IF(F29="Não",1,0) -> 0 | I29: =IF(AND(E29="Não",F29="Não"),1,0) -> 0 | J29: =IF(OR(E29="Não",F29="Não"),1,0) -> 0
A30: RO | B30: Ariquemes | C30: 1100023 | D30: =ROUNDDOWN(C30/10,0) -> 110002 | E30: ='Base de dados STN'!D30 -> SIM | F30: =IF(ISERROR(VLOOKUP(D30,FNDE!$C$2:$D$932,1,FALSE)),"SIM","NÃO") -> SIM | G30: =IF(E30="Não",1,0) -> 0 | H30: =IF(F30="Não",1,0) -> 0 | I30: =IF(AND(E30="Não",F30="Não"),1,0) -> 0 | J30: =IF(OR(E30="Não",F30="Não"),1,0) -> 0
A31: RO | B31: Cabixi | C31: 1100031 | D31: =ROUNDDOWN(C31/10,0) -> 110003 | E31: ='Base de dados STN'!D31 -> SIM | F31: =IF(ISERROR(VLOOKUP(D31,FNDE!$C$2:$D$932,1,FALSE)),"SIM","NÃO") -> SIM | G31: =IF(E31="Não",1,0) -> 0 | H31: =IF(F31="Não",1,0) -> 0 | I31: =IF(AND(E31="Não",F31="Não"),1,0) -> 0 | J31: =IF(OR(E31="Não",F31="Não"),1,0) -> 0
A32: RO | B32: Cacoal | C32: 1100049 | D32: =ROUNDDOWN(C32/10,0) -> 110004 | E32: ='Base de dados STN'!D32 -> SIM | F32: =IF(ISERROR(VLOOKUP(D32,FNDE!$C$2:$D$932,1,FALSE)),"SIM","NÃO") -> SIM | G32: =IF(E32="Não",1,0) -> 0 | H32: =IF(F32="Não",1,0) -> 0 | I32: =IF(AND(E32="Não",F32="Não"),1,0) -> 0 | J32: =IF(OR(E32="Não",F32="Não"),1,0) -> 0
A33: RO | B33: Cerejeiras | C33: 1100056 | D33: =ROUNDDOWN(C33/10,0) -> 110005 | E33: ='Base de dados STN'!D33 -> SIM | F33: =IF(ISERROR(VLOOKUP(D33,FNDE!$C$2:$D$932,1,FALSE)),"SIM","NÃO") -> SIM | G33: =IF(E33="Não",1,0) -> 0 | H33: =IF(F33="Não",1,0) -> 0 | I33: =IF(AND(E33="Não",F33="Não"),1,0) -> 0 | J33: =IF(OR(E33="Não",F33="Não"),1,0) -> 0
A34: RO | B34: Colorado do Oeste | C34: 1100064 | D34: =ROUNDDOWN(C34/10,0) -> 110006 | E34: ='Base de dados STN'!D34 -> SIM | F34: =IF(ISERROR(VLOOKUP(D34,FNDE!$C$2:$D$932,1,FALSE)),"SIM","NÃO") -> SIM | G34: =IF(E34="Não",1,0) -> 0 | H34: =IF(F34="Não",1,0) -> 0 | I34: =IF(AND(E34="Não",F34="Não"),1,0) -> 0 | J34: =IF(OR(E34="Não",F34="Não"),1,0) -> 0
A35: RO | B35: Corumbiara | C35: 1100072 | D35: =ROUNDDOWN(C35/10,0) -> 110007 | E35: ='Base de dados STN'!D35 -> SIM | F35: =IF(ISERROR(VLOOKUP(D35,FNDE!$C$2:$D$932,1,FALSE)),"SIM","NÃO") -> SIM | G35: =IF(E35="Não",1,0) -> 0 | H35: =IF(F35="Não",1,0) -> 0 | I35: =IF(AND(E35="Não",F35="Não"),1,0) -> 0 | J35: =IF(OR(E35="Não",F35="Não"),1,0) -> 0
A36: RO | B36: Costa Marques | C36: 1100080 | D36: =ROUNDDOWN(C36/10,0) -> 110008 | E36: ='Base de dados STN'!D36 -> SIM | F36: =IF(ISERROR(VLOOKUP(D36,FNDE!$C$2:$D$932,1,FALSE)),"SIM","NÃO") -> SIM | G36: =IF(E36="Não",1,0) -> 0 | H36: =IF(F36="Não",1,0) -> 0 | I36: =IF(AND(E36="Não",F36="Não"),1,0) -> 0 | J36: =IF(OR(E36="Não",F36="Não"),1,0) -> 0
A37: RO | B37: Espigão D'Oeste | C37: 1100098 | D37: =ROUNDDOWN(C37/10,0) -> 110009 | E37: ='Base de dados STN'!D37 -> SIM | F37: =IF(ISERROR(VLOOKUP(D37,FNDE!$C$2:$D$932,1,FALSE)),"SIM","NÃO") -> SIM | G37: =IF(E37="Não",1,0) -> 0 | H37: =IF(F37="Não",1,0) -> 0 | I37: =IF(AND(E37="Não",F37="Não"),1,0) -> 0 | J37: =IF(OR(E37="Não",F37="Não"),1,0) -> 0
A38: RO | B38: Guajará-Mirim | C38: 1100106 | D38: =ROUNDDOWN(C38/10,0) -> 110010 | E38: ='Base de dados STN'!D38 -> SIM | F38: =IF(ISERROR(VLOOKUP(D38,FNDE!$C$2:$D$932,1,FALSE)),"SIM","NÃO") -> SIM | G38: =IF(E38="Não",1,0) -> 0 | H38: =IF(F38="Não",1,0) -> 0 | I38: =IF(AND(E38="Não",F38="Não"),1,0) -> 0 | J38: =IF(OR(E38="Não",F38="Não"),1,0) -> 0
A39: RO | B39: Jaru | C39: 1100114 | D39: =ROUNDDOWN(C39/10,0) -> 110011 | E39: ='Base de dados STN'!D39 -> SIM | F39: =IF(ISERROR(VLOOKUP(D39,FNDE!$C$2:$D$932,1,FALSE)),"SIM","NÃO") -> SIM | G39: =IF(E39="Não",1,0) -> 0 | H39: =IF(F39="Não",1,0) -> 0 | I39: =IF(AND(E39="Não",F39="Não"),1,0) -> 0 | J39: =IF(OR(E39="Não",F39="Não"),1,0) -> 0
A40: RO | B40: Ji-Paraná | C40: 1100122 | D40: =ROUNDDOWN(C40/10,0) -> 110012 | E40: ='Base de dados STN'!D40 -> SIM | F40: =IF(ISERROR(VLOOKUP(D40,FNDE!$C$2:$D$932,1,FALSE)),"SIM","NÃO") -> SIM | G40: =IF(E40="Não",1,0) -> 0 | H40: =IF(F40="Não",1,0) -> 0 | I40: =IF(AND(E40="Não",F40="Não"),1,0) -> 0 | J40: =IF(OR(E40="Não",F40="Não"),1,0) -> 0
... A5597: GO | B5597: Vila Propício | C5597: 5222302 | D5597: =ROUNDDOWN(C5597/10,0) -> 522230 | E5597: ='Base de dados STN'!D5597 -> SIM | F5597: =IF(ISERROR(VLOOKUP(D5597,FNDE!$C$2:$D$932,1,FALSE)),"SIM","NÃO") -> SIM | G5597: =IF(E5597="Não",1,0) -> 0 | H5597: =IF(F5597="Não",1,0) -> 0 | I5597: =IF(AND(E5597="Não",F5597="Não"),1,0) -> 0 | J5597: =IF(OR(E5597="Não",F5597="Não"),1,0) -> 0
G5598: =SUM(G2:G5597) -> 17 | H5598: =SUM(H2:H5597) -> 60 | I5598: =SUM(I2:I5597) -> 6 | J5598: =SUM(J2:J5597) -> 71
J5600: =116/237-1 -> -0.51054852
J5601: =116/165-1 -> -0.2969697

Sheet Comunicado formulas
A1: UF | B1: Ente Federado | C1: Código IBGE | D1: Veficação preliminar do disposto no § 4º do art. 13 da Lei nº 14.113/20 | E1: Pendência identificada | F1: Habilitação 163-A? | G1: Habilitação art. 38?
A2: RO | B2: Rondônia | C2: 11 | D2: =IF(AND(F2="Sim",G2="Sim"),$I$2,IF(AND(F2="Não",G2="Não"),$I$5,IF(F2="Não",$I$3,$I$4))) -> Habilitado para o cálculo do VAAT. | E2: =IF(AND(F2="NÃO",G2="NÃO"),'Base de dados STN'!E2&" e não transmitiu ao SIOPE os dados do ano de 2025.",IF(AND(F2="NÃO",G2="SIM"),'Base de dados STN'!E2&".",IF(AND(F2="SIM",G2="NÃO"),"Não transmitiu ao SIOPE os dados do ano de 2025.",""))) | F2: ='Compilação STN e FNDE'!E2 -> SIM | G2: ='Compilação STN e FNDE'!F2 -> SIM | I2: Habilitado para o cálculo do VAAT.
A3: AC | B3: Acre | C3: 12 | D3: =IF(AND(F3="Sim",G3="Sim"),$I$2,IF(AND(F3="Não",G3="Não"),$I$5,IF(F3="Não",$I$3,$I$4))) -> Habilitado para o cálculo do VAAT. | E3: =IF(AND(F3="NÃO",G3="NÃO"),'Base de dados STN'!E3&" e não transmitiu ao SIOPE os dados do ano de 2025.",IF(AND(F3="NÃO",G3="SIM"),'Base de dados STN'!E3&".",IF(AND(F3="SIM",G3="NÃO"),"Não transmitiu ao SIOPE os dados do ano de 2025.",""))) | F3: ='Compilação STN e FNDE'!E3 -> SIM | G3: ='Compilação STN e FNDE'!F3 -> SIM | I3: Inobservância do art. 163-A da Constituição Federal.
A4: AM | B4: Amazonas | C4: 13 | D4: =IF(AND(F4="Sim",G4="Sim"),$I$2,IF(AND(F4="Não",G4="Não"),$I$5,IF(F4="Não",$I$3,$I$4))) -> Habilitado para o cálculo do VAAT. | E4: =IF(AND(F4="NÃO",G4="NÃO"),'Base de dados STN'!E4&" e não transmitiu ao SIOPE os dados do ano de 2025.",IF(AND(F4="NÃO",G4="SIM"),'Base de dados STN'!E4&".",IF(AND(F4="SIM",G4="NÃO"),"Não transmitiu ao SIOPE os dados do ano de 2025.",""))) | F4: ='Compilação STN e FNDE'!E4 -> SIM | G4: ='Compilação STN e FNDE'!F4 -> SIM | I4: Inobservância do art. 38 da Lei nº 14.113/20.
A5: RR | B5: Roraima | C5: 14 | D5: =IF(AND(F5="Sim",G5="Sim"),$I$2,IF(AND(F5="Não",G5="Não"),$I$5,IF(F5="Não",$I$3,$I$4))) -> Habilitado para o cálculo do VAAT. | E5: =IF(AND(F5="NÃO",G5="NÃO"),'Base de dados STN'!E5&" e não transmitiu ao SIOPE os dados do ano de 2025.",IF(AND(F5="NÃO",G5="SIM"),'Base de dados STN'!E5&".",IF(AND(F5="SIM",G5="NÃO"),"Não transmitiu ao SIOPE os dados do ano de 2025.",""))) | F5: ='Compilação STN e FNDE'!E5 -> SIM | G5: ='Compilação STN e FNDE'!F5 -> SIM | I5: Inobservância do art. 163-A da CF e do art. 38 da Lei 14.113/20.
A6: PA | B6: Pará | C6: 15 | D6: =IF(AND(F6="Sim",G6="Sim"),$I$2,IF(AND(F6="Não",G6="Não"),$I$5,IF(F6="Não",$I$3,$I$4))) -> Habilitado para o cálculo do VAAT. | E6: =IF(AND(F6="NÃO",G6="NÃO"),'Base de dados STN'!E6&" e não transmitiu ao SIOPE os dados do ano de 2025.",IF(AND(F6="NÃO",G6="SIM"),'Base de dados STN'!E6&".",IF(AND(F6="SIM",G6="NÃO"),"Não transmitiu ao SIOPE os dados do ano de 2025.",""))) | F6: ='Compilação STN e FNDE'!E6 -> SIM | G6: ='Compilação STN e FNDE'!F6 -> SIM
A7: AP | B7: Amapá | C7: 16 | D7: =IF(AND(F7="Sim",G7="Sim"),$I$2,IF(AND(F7="Não",G7="Não"),$I$5,IF(F7="Não",$I$3,$I$4))) -> Habilitado para o cálculo do VAAT. | E7: =IF(AND(F7="NÃO",G7="NÃO"),'Base de dados STN'!E7&" e não transmitiu ao SIOPE os dados do ano de 2025.",IF(AND(F7="NÃO",G7="SIM"),'Base de dados STN'!E7&".",IF(AND(F7="SIM",G7="NÃO"),"Não transmitiu ao SIOPE os dados do ano de 2025.",""))) | F7: ='Compilação STN e FNDE'!E7 -> SIM | G7: ='Compilação STN e FNDE'!F7 -> SIM
A8: TO | B8: Tocantins | C8: 17 | D8: =IF(AND(F8="Sim",G8="Sim"),$I$2,IF(AND(F8="Não",G8="Não"),$I$5,IF(F8="Não",$I$3,$I$4))) -> Habilitado para o cálculo do VAAT. | E8: =IF(AND(F8="NÃO",G8="NÃO"),'Base de dados STN'!E8&" e não transmitiu ao SIOPE os dados do ano de 2025.",IF(AND(F8="NÃO",G8="SIM"),'Base de dados STN'!E8&".",IF(AND(F8="SIM",G8="NÃO"),"Não transmitiu ao SIOPE os dados do ano de 2025.",""))) | F8: ='Compilação STN e FNDE'!E8 -> SIM | G8: ='Compilação STN e FNDE'!F8 -> SIM
A9: MA | B9: Maranhão | C9: 21 | D9: =IF(AND(F9="Sim",G9="Sim"),$I$2,IF(AND(F9="Não",G9="Não"),$I$5,IF(F9="Não",$I$3,$I$4))) -> Habilitado para o cálculo do VAAT. | E9: =IF(AND(F9="NÃO",G9="NÃO"),'Base de dados STN'!E9&" e não transmitiu ao SIOPE os dados do ano de 2025.",IF(AND(F9="NÃO",G9="SIM"),'Base de dados STN'!E9&".",IF(AND(F9="SIM",G9="NÃO"),"Não transmitiu ao SIOPE os dados do ano de 2025.",""))) | F9: ='Compilação STN e FNDE'!E9 -> SIM | G9: ='Compilação STN e FNDE'!F9 -> SIM
A10: PI | B10: Piauí | C10: 22 | D10: =IF(AND(F10="Sim",G10="Sim"),$I$2,IF(AND(F10="Não",G10="Não"),$I$5,IF(F10="Não",$I$3,$I$4))) -> Habilitado para o cálculo do VAAT. | E10: =IF(AND(F10="NÃO",G10="NÃO"),'Base de dados STN'!E10&" e não transmitiu ao SIOPE os dados do ano de 2025.",IF(AND(F10="NÃO",G10="SIM"),'Base de dados STN'!E10&".",IF(AND(F10="SIM",G10="NÃO"),"Não transmitiu ao SIOPE os dados do ano de 2025.",""))) | F10: ='Compilação STN e FNDE'!E10 -> SIM | G10: ='Compilação STN e FNDE'!F10 -> SIM
A11: CE | B11: Ceará | C11: 23 | D11: =IF(AND(F11="Sim",G11="Sim"),$I$2,IF(AND(F11="Não",G11="Não"),$I$5,IF(F11="Não",$I$3,$I$4))) -> Habilitado para o cálculo do VAAT. | E11: =IF(AND(F11="NÃO",G11="NÃO"),'Base de dados STN'!E11&" e não transmitiu ao SIOPE os dados do ano de 2025.",IF(AND(F11="NÃO",G11="SIM"),'Base de dados STN'!E11&".",IF(AND(F11="SIM",G11="NÃO"),"Não transmitiu ao SIOPE os dados do ano de 2025.",""))) | F11: ='Compilação STN e FNDE'!E11 -> SIM | G11: ='Compilação STN e FNDE'!F11 -> SIM
A12: RN | B12: Rio Grande do Norte | C12: 24 | D12: =IF(AND(F12="Sim",G12="Sim"),$I$2,IF(AND(F12="Não",G12="Não"),$I$5,IF(F12="Não",$I$3,$I$4))) -> Habilitado para o cálculo do VAAT. | E12: =IF(AND(F12="NÃO",G12="NÃO"),'Base de dados STN'!E12&" e não transmitiu ao SIOPE os dados do ano de 2025.",IF(AND(F12="NÃO",G12="SIM"),'Base de dados STN'!E12&".",IF(AND(F12="SIM",G12="NÃO"),"Não transmitiu ao SIOPE os dados do ano de 2025.",""))) | F12: ='Compilação STN e FNDE'!E12 -> SIM | G12: ='Compilação STN e FNDE'!F12 -> SIM
A13: PB | B13: Paraíba | C13: 25 | D13: =IF(AND(F13="Sim",G13="Sim"),$I$2,IF(AND(F13="Não",G13="Não"),$I$5,IF(F13="Não",$I$3,$I$4))) -> Habilitado para o cálculo do VAAT. | E13: =IF(AND(F13="NÃO",G13="NÃO"),'Base de dados STN'!E13&" e não transmitiu ao SIOPE os dados do ano de 2025.",IF(AND(F13="NÃO",G13="SIM"),'Base de dados STN'!E13&".",IF(AND(F13="SIM",G13="NÃO"),"Não transmitiu ao SIOPE os dados do ano de 2025.",""))) | F13: ='Compilação STN e FNDE'!E13 -> SIM | G13: ='Compilação STN e FNDE'!F13 -> SIM
A14: PE | B14: Pernambuco | C14: 26 | D14: =IF(AND(F14="Sim",G14="Sim"),$I$2,IF(AND(F14="Não",G14="Não"),$I$5,IF(F14="Não",$I$3,$I$4))) -> Habilitado para o cálculo do VAAT. | E14: =IF(AND(F14="NÃO",G14="NÃO"),'Base de dados STN'!E14&" e não transmitiu ao SIOPE os dados do ano de 2025.",IF(AND(F14="NÃO",G14="SIM"),'Base de dados STN'!E14&".",IF(AND(F14="SIM",G14="NÃO"),"Não transmitiu ao SIOPE os dados do ano de 2025.",""))) | F14: ='Compilação STN e FNDE'!E14 -> SIM | G14: ='Compilação STN e FNDE'!F14 -> SIM
A15: AL | B15: Alagoas | C15: 27 | D15: =IF(AND(F15="Sim",G15="Sim"),$I$2,IF(AND(F15="Não",G15="Não"),$I$5,IF(F15="Não",$I$3,$I$4))) -> Habilitado para o cálculo do VAAT. | E15: =IF(AND(F15="NÃO",G15="NÃO"),'Base de dados STN'!E15&" e não transmitiu ao SIOPE os dados do ano de 2025.",IF(AND(F15="NÃO",G15="SIM"),'Base de dados STN'!E15&".",IF(AND(F15="SIM",G15="NÃO"),"Não transmitiu ao SIOPE os dados do ano de 2025.",""))) | F15: ='Compilação STN e FNDE'!E15 -> SIM | G15: ='Compilação STN e FNDE'!F15 -> SIM
A16: SE | B16: Sergipe | C16: 28 | D16: =IF(AND(F16="Sim",G16="Sim"),$I$2,IF(AND(F16="Não",G16="Não"),$I$5,IF(F16="Não",$I$3,$I$4))) -> Habilitado para o cálculo do VAAT. | E16: =IF(AND(F16="NÃO",G16="NÃO"),'Base de dados STN'!E16&" e não transmitiu ao SIOPE os dados do ano de 2025.",IF(AND(F16="NÃO",G16="SIM"),'Base de dados STN'!E16&".",IF(AND(F16="SIM",G16="NÃO"),"Não transmitiu ao SIOPE os dados do ano de 2025.",""))) | F16: ='Compilação STN e FNDE'!E16 -> SIM | G16: ='Compilação STN e FNDE'!F16 -> SIM
A17: BA | B17: Bahia | C17: 29 | D17: =IF(AND(F17="Sim",G17="Sim"),$I$2,IF(AND(F17="Não",G17="Não"),$I$5,IF(F17="Não",$I$3,$I$4))) -> Habilitado para o cálculo do VAAT. | E17: =IF(AND(F17="NÃO",G17="NÃO"),'Base de dados STN'!E17&" e não transmitiu ao SIOPE os dados do ano de 2025.",IF(AND(F17="NÃO",G17="SIM"),'Base de dados STN'!E17&".",IF(AND(F17="SIM",G17="NÃO"),"Não transmitiu ao SIOPE os dados do ano de 2025.",""))) | F17: ='Compilação STN e FNDE'!E17 -> SIM | G17: ='Compilação STN e FNDE'!F17 -> SIM
... A5597: GO | B5597: Vila Propício | C5597: 5222302 | D5597: =IF(AND(F5597="Sim",G5597="Sim"),$I$2,IF(AND(F5597="Não",G5597="Não"),$I$5,IF(F5597="Não",$I$3,$I$4))) -> Habilitado para o cálculo do VAAT. | E5597: =IF(AND(F5597="NÃO",G5597="NÃO"),'Base de dados STN'!E5597&" e não transmitiu ao SIOPE os dados do ano de 2025.",IF(AND(F5597="NÃO",G5597="SIM"),'Base de dados STN'!E5597&".",IF(AND(F5597="SIM",G5597="NÃO"),"Não transmitiu ao SIOPE os dados do ano de 2025.",""))) | F5597: ='Compilação STN e FNDE'!E5597 -> SIM | G5597: ='Compilação STN e FNDE'!F5597 -> SIM

Sheet Final 4agosto2026
A1: UF | B1: Ente Federado | C1: Código IBGE | D1: Veficação preliminar do disposto no § 4º do art. 13 da Lei nº 14.113/20 | E1: Pendência identificada
A2: AC | B2: Acre | C2: 12 | D2: Habilitado para o cálculo do VAAT.
A3: AC | B3: Acrelândia | C3: 1200013 | D3: Habilitado para o cálculo do VAAT.
A4: AC | B4: Assis Brasil | C4: 1200054 | D4: Habilitado para o cálculo do VAAT.
A5: AC | B5: Brasiléia | C5: 1200104 | D5: Habilitado para o cálculo do VAAT.
A6: AC | B6: Bujari | C6: 1200138 | D6: Habilitado para o cálculo do VAAT.
A7: AC | B7: Capixaba | C7: 1200179 | D7: Habilitado para o cálculo do VAAT.
A8: AC | B8: Cruzeiro do Sul | C8: 1200203 | D8: Habilitado para o cálculo do VAAT.
A9: AC | B9: Epitaciolândia | C9: 1200252 | D9: Inobservância do art. 38 da Lei nº 14.113/20. | E9: Não transmitiu ao SIOPE os dados do ano de 2025.
A10: AC | B10: Feijó | C10: 1200302 | D10: Habilitado para o cálculo do VAAT.
A11: AC | B11: Jordão | C11: 1200328 | D11: Habilitado para o cálculo do VAAT.
A12: AC | B12: Mâncio Lima | C12: 1200336 | D12: Habilitado para o cálculo do VAAT.
A13: AC | B13: Manoel Urbano | C13: 1200344 | D13: Habilitado para o cálculo do VAAT.
A14: AC | B14: Marechal Thaumaturgo | C14: 1200351 | D14: Habilitado para o cálculo do VAAT.
A15: AC | B15: Plácido de Castro | C15: 1200385 | D15: Habilitado para o cálculo do VAAT.
A16: AC | B16: Porto Walter | C16: 1200393 | D16: Habilitado para o cálculo do VAAT.
A17: AC | B17: Rio Branco | C17: 1200401 | D17: Habilitado para o cálculo do VAAT.
A18: AC | B18: Rodrigues Alves | C18: 1200427 | D18: Habilitado para o cálculo do VAAT.
A19: AC | B19: Santa Rosa do Purus | C19: 1200435 | D19: Habilitado para o cálculo do VAAT.
A20: AC | B20: Senador Guiomard | C20: 1200450 | D20: Habilitado para o cálculo do VAAT.
A21: AC | B21: Sena Madureira | C21: 1200500 | D21: Habilitado para o cálculo do VAAT.
... A138: AM | B138: Benjamin Constant | C138: 1300607 | D138: Habilitado para o cálculo do VAAT.
A139: AM | B139: Beruri | C139: 1300631 | D139: Inobservância do art. 38 da Lei nº 14.113/20. | E139: Não transmitiu ao SIOPE os dados do ano de 2025.
A140: AM | B140: Boa Vista do Ramos | C140: 1300680 | D140: Habilitado para o cálculo do VAAT.
A141: AM | B141: Boca do Acre | C141: 1300706 | D141: Inobservância do art. 38 da Lei nº 14.113/20. | E141: Não transmitiu ao SIOPE os dados do ano de 2025.
A142: AM | B142: Borba | C142: 1300805 | D142: Habilitado para o cálculo do VAAT.
A143: AM | B143: Caapiranga | C143: 1300839 | D143: Inobservância do art. 38 da Lei nº 14.113/20. | E143: Não transmitiu ao SIOPE os dados do ano de 2025.
A144: AM | B144: Canutama | C144: 1300904 | D144: Habilitado para o cálculo do VAAT.
A145: AM | B145: Carauari | C145: 1301001 | D145: Habilitado para o cálculo do VAAT.
A146: AM | B146: Careiro | C146: 1301100 | D146: Habilitado para o cálculo do VAAT.
A147: AM | B147: Careiro da Várzea | C147: 1301159 | D147: Habilitado para o cálculo do VAAT.
A148: AM | B148: Coari | C148: 1301209 | D148: Habilitado para o cálculo do VAAT.
A149: AM | B149: Codajás | C149: 1301308 | D149: Habilitado para o cálculo do VAAT.
A150: AM | B150: Eirunepé | C150: 1301407 | D150: Inobservância do art. 38 da Lei nº 14.113/20. | E150: Não transmitiu ao SIOPE os dados do ano de 2025.
A151: AM | B151: Envira | C151: 1301506 | D151: Habilitado para o cálculo do VAAT.
A152: AM | B152: Fonte Boa | C152: 1301605 | D152: Habilitado para o cálculo do VAAT.
A153: AM | B153: Guajará | C153: 1301654 | D153: Habilitado para o cálculo do VAAT.
A154: AM | B154: Humaitá | C154: 1301704 | D154: Habilitado para o cálculo do VAAT.
A155: AM | B155: Ipixuna | C155: 1301803 | D155: Inobservância do art. 38 da Lei nº 14.113/20. | E155: Não transmitiu ao SIOPE os dados do ano de 2025.
A156: AM | B156: Iranduba | C156: 1301852 | D156: Habilitado para o cálculo do VAAT.
...
